{
    "registryname": "advanced_mobspawner",
    "localizedname": "Advanced Mob Spawner",
    "requires-blueprint": true,
	"color": "5B666C",
	"parts": [
        {
            "x": 1,
            "y": 0,
            "z": 0,
            "elements": [
				"enderio:block_alloy@6"
				]
        },
        {
            "x": -1,
            "y": 0,
            "z": 0,
            "elements": [
				"enderio:block_alloy@6"
				]
        },
        {
            "x": 0,
            "y": 0,
            "z": -1,
            "elements": [
				"enderio:block_alloy@6"
				]
        },

        {
            "x": 1,
            "y": 0,
            "z": -1,
            "elements": [
				"enderio:block_alloy@6"
				]
        },
        {
            "x": -1,
            "y": 0,
            "z": -1,
            "elements": [
				"enderio:block_alloy@6"
				]
        },
        {
            "x": -1,
            "y": 0,
            "z": -2,
            "elements": [
				"enderio:block_alloy@6"
				]
        },

        {
            "x": 1,
            "y": 0,
            "z": -2,
            "elements": [
				"enderio:block_alloy@6"
				]
        },
        {
            "x": 0,
            "y": 0,
            "z": -2,
            "elements": [
				"enderio:block_alloy@6"
				]
        },
        {
            "x": 0,
            "y": 1,
            "z": 0,
            "elements": [
				"rftools:screen_controller"
				]
        },

        {
            "x": -1,
            "y": 1,
            "z": -1,
            "elements": [
				"casings_item"
				]
        },
        {
            "x": 1,
            "y": 1,
            "z": -1,
            "elements": [
				"casings_item"
				]
        },
        {
            "x": 0,
            "y": 1,
            "z": -2,
            "elements": [
				"modularmachinery:blockenergyinputhatch"
				]
        },
        {
            "x": -1,
            "y": 1,
            "z": 0,
            "elements": [
				"enderio:block_alloy@0"
				]
        },
        {
            "x": 1,
            "y": 1,
            "z": 0,
            "elements": [
				"enderio:block_alloy@0"
				]
        },
        {
            "x": -1,
            "y": 1,
            "z": -2,
            "elements": [
				"enderio:block_alloy@0"
				]
        },
        {
            "x": 1,
            "y": 1,
            "z": -2,
            "elements": [
				"enderio:block_alloy@0"
				]
        },

        {
            "x": 0,
            "y": 1,
            "z": -1,
            "elements": [
				"rftools:spawner"
				]
        },
        {
            "x": 0,
            "y": 2,
            "z": -1,
            "elements": [
				"rftools:spawner"
				]
        },
        {
            "x": 0,
            "y": 3,
            "z": -1,
            "elements": [
				"rftools:spawner"
				]
        },
        {
            "x": 0,
            "y": 4,
            "z": -1,
            "elements": [
				"modularmachinery:blockcasing@1"
				]
        },

        {
            "x": 1,
            "y": 4,
            "z": 0,
            "elements": [
				"modularmachinery:blockcasing@1"
				]
        },
        {
            "x": -1,
            "y": 4,
            "z": 0,
            "elements": [
				"modularmachinery:blockcasing@1"
				]
        },
        {
            "x": 0,
            "y": 4,
            "z": 0,
            "elements": [
				"modularmachinery:blockcasing@1"
				]
        },

        {
            "x": 1,
            "y": 4,
            "z": -1,
            "elements": [
				"modularmachinery:blockcasing@1"
			]
        },
        {
            "x": -1,
            "y": 4,
            "z": -1,
            "elements": [
				"modularmachinery:blockcasing@1"
				]
        },
        {
            "x": 1,
            "y": 4,
            "z": -2,
            "elements": [
				"modularmachinery:blockcasing@1"
				]
        },
        {
            "x": -1,
            "y": 4,
            "z": -2,
            "elements": [
				"modularmachinery:blockcasing@1"
				]
        },
        {
            "x": 0,
            "y": 4,
            "z": -2,
            "elements": [
				"modularmachinery:blockcasing@1"
				]
        },
        {
            "x": 0,
            "y": 2,
            "z": 0,
            "elements": [
				"enderio:block_alloy@0"
				]
        },
        {
            "x": -1,
            "y": 2,
            "z": 0,
            "elements": [
				"enderio:block_alloy@0"
				]
        },
        {
            "x": 1,
            "y": 2,
            "z": 0,
            "elements": [
				"enderio:block_alloy@0"
				]
        },
        {
            "x": 1,
            "y": 2,
            "z": -1,
            "elements": [
				"enderio:block_alloy@0"
				]
        },
	    {
            "x": -1,
            "y": 2,
            "z": -1,
            "elements": [
				"enderio:block_alloy@0"
				]
        },
        {
            "x": 1,
            "y": 2,
            "z": -2,
            "elements": [
				"enderio:block_alloy@0"
				]
        },
        {
            "x": 0,
            "y": 2,
            "z": -2,
            "elements": [
				"enderio:block_alloy@0"
				]
        },
        {
            "x": -1,
            "y": 2,
            "z": -2,
            "elements": [
				"enderio:block_alloy@0"
				]
        },
	    {
            "x": 0,
            "y": 3,
            "z": 0,
            "elements": [
				"enderio:block_alloy@0"
				]
        },
        {
            "x": -1,
            "y": 3,
            "z": 0,
            "elements": [
				"enderio:block_alloy@0"
				]
        },
        {
            "x": 1,
            "y": 3,
            "z": 0,
            "elements": [
				"enderio:block_alloy@0"
				]
        },
        {
            "x": 1,
            "y": 3,
            "z": -1,
            "elements": [
				"enderio:block_alloy@0"
				]
        },
	    {
            "x": -1,
            "y": 3,
            "z": -1,
            "elements": [
				"enderio:block_alloy@0"
				]
        },
        {
            "x": 1,
            "y": 3,
            "z": -2,
            "elements": [
				"enderio:block_alloy@0"
				]
        },
        {
            "x": 0,
            "y": 3,
            "z": -2,
            "elements": [
				"enderio:block_alloy@0"
				]
        },
        {
            "x": -1,
            "y": 3,
            "z": -2,
            "elements": [
				"enderio:block_alloy@0"
				]
        }
    ]
}